<?xml version="1.0" ?>
<robot name="irbp_a750" xmlns:xacro="http://ros.org/wiki/xacro">
 <xacro:property name="name" value="irbp_a750/" />

  <link name="${name}base_link">
    <visual>
      <geometry>
        <mesh filename="package://simtech_workcell/meshes/irbp_a750/visual/irbp_a750_0.stl" scale="0.001 0.001 0.001"/>
      </geometry>
      <material name="black">
        <color rgba="0.1 0.1 0.1 1" />
      </material>
    </visual>
    <collision>
      <geometry>
        <mesh filename="package://simtech_workcell/meshes/irbp_a750/collision/irbp_a750_0.stl" scale="0.001 0.001 0.001"/>
      </geometry>
      <material name="yellow">
        <color rgba="0 1 1 1" />
      </material>
    </collision>
  </link>
  <link name="${name}link_1">
    <visual>
      <geometry>
        <mesh filename="package://simtech_workcell/meshes/irbp_a750/visual/irbp_a750_1.stl" scale="0.001 0.001 0.001"/>
      </geometry>
      <material name="abb_orange">
        <color rgba="1 0.43 0 1" />
      </material>
    </visual>
    <collision>
      <geometry>
        <mesh filename="package://simtech_workcell/meshes/irbp_a750/collision/irbp_a750_1.stl" scale="0.001 0.001 0.001"/>
      </geometry>
      <material name="yellow" />
    </collision>
  </link>
  <link name="${name}link_2">
    <visual>
      <geometry>
        <mesh filename="package://simtech_workcell/meshes/irbp_a750/visual/irbp_a750_2.stl" scale="0.001 0.001 0.001"/>
      </geometry>
      <material name="abb_orange" />
    </visual>
    <collision>
      <geometry>
        <mesh filename="package://simtech_workcell/meshes/irbp_a750/collision/irbp_a750_2.stl" scale="0.001 0.001 0.001"/>
      </geometry>
      <material name="yellow" />
    </collision>
  </link>
  <link name="${name}link_3">
    <visual>
      <geometry>
        <mesh filename="package://simtech_workcell/meshes/irbp_a750/visual/irbp_a750_3.stl" scale="0.001 0.001 0.001"/>
      </geometry>
      <material name="abb_orange" />
    </visual>
    <collision>
      <geometry>
        <mesh filename="package://simtech_workcell/meshes/irbp_a750/collision/irbp_a750_3.stl" scale="0.001 0.001 0.001"/>
      </geometry>
      <material name="yellow" />
    </collision>
  </link>
  <link name="${name}link_4">
    <visual>
      <geometry>
        <mesh filename="package://simtech_workcell/meshes/irbp_a750/visual/irbp_a750_4.stl" scale="0.001 0.001 0.001"/>
      </geometry>
      <material name="gray">
          <color rgba="0.4 0.4 0.4 0.8"/>
      </material>
    </visual>
    <collision>
      <geometry>
        <mesh filename="package://simtech_workcell/meshes/irbp_a750/collision/irbp_a750_4.stl" scale="0.001 0.001 0.001"/>
      </geometry>
      <material name="yellow" />
    </collision>
  </link>
  <link name="${name}tool0" />

  <joint name="${name}joint1" type="fixed">
    <parent link="${name}base_link" />
    <child link="${name}link_1" />
    <origin rpy="0 0 0" xyz="0 0.1 0" />
    <axis xyz="0 0 1" />
  </joint>
  <joint name="${name}joint2" type="revolute">
    <parent link="${name}link_1" />
    <child link="${name}link_2" />
    <origin rpy="0 0 0" xyz="0 0.04 0.4" />
    <axis xyz="1 0 0" />
    <limit effort="100" lower="-3.1590" upper="3.1590" velocity="2.6180" />
  </joint>
  <joint name="${name}joint3" type="fixed">
    <parent link="${name}link_2" />
    <child link="${name}link_3" />
    <origin rpy="0 0 0" xyz="0.01 0.01 0" />
    <axis xyz="0 1 0" />
  </joint>
  <joint name="${name}joint4" type="continuous">
    <parent link="${name}link_3" />
    <child link="${name}link_4" />
    <origin rpy="0 0 0" xyz="0 0 0.43" />
    <axis xyz="0 0 1" />
    <limit effort="100" velocity="3.1416" />
  </joint>
  <joint name="${name}tool0" type="fixed">
    <parent link="${name}link_4" />
    <child link="${name}tool0" />
    <origin rpy="0 0 0" xyz="0 0 0" />
  </joint>
  
  <!-- Table -->
    <link name="table0">
        <visual>
            <geometry>
                <mesh filename="package://simtech_workcell/meshes/table/table.stl"/>
            </geometry>
            <material name="gray">
                <color rgba="0.4 0.4 0.4 0.8"/>
            </material>
        </visual>
    </link>

    <joint name="table0" type="fixed">
        <parent link="irbp_a750/tool0"/>
        <child link="table0"/>
        <origin xyz="0 0 0" rpy="0 0 0"/>
        <axis xyz="0 0 1"/>
    </joint>


</robot>
